Workbook

Sheet Parámetros
A1: PARÁMETROS — Mercado Libre Argentina (editable)
A2: Modificá los valores en azul cuando Mercado Libre actualice sus tarifas. Todas las fórmulas de la hoja "Calculadora" recalculan solas. Ver hoja "Notas y Fuentes" para el detalle de cada supuesto.
A4: 1. COMISIÓN POR CATEGORÍA (% sobre precio de venta)
B5: Categoría | C5: Comisión Clásica | D5: Comisión Premium
B6: Supermercado | C6: 0.118 | D6: 0.148
B7: Electrónica, Audio y Video | C7: 0.15 | D7: 0.1714
B8: Computación | C8: 0.15 | D8: 0.1714
B9: Celulares y Telefonía | C9: 0.14 | D9: 0.165
B10: Accesorios para Vehículos | C10: 0.13 | D10: 0.16
B11: Hogar, Muebles y Jardín | C11: 0.135 | D11: 0.16
B12: Deportes y Fitness | C12: 0.135 | D12: 0.16
B13: Ropa y Calzado | C13: 0.135 | D13: 0.16
B14: Herramientas | C14: 0.135 | D14: 0.16
B15: Otras categorías (default) | C15: 0.135 | D15: 0.165
A16: Fuente: relevamiento de comisiones ML Argentina 2026 (DigitalSellers, SpomBridge, WooSync, Base). Los % exactos varían por sub-categoría y provincia — verificá el % real al publicar tu producto en tu cuenta de ML.
A18: 2. UMBRAL DE ENVÍO GRATIS OBLIGATORIO
B19: Envío gratis obligatorio desde ($) | C19: 33000
A20: Por debajo de este precio, el vendedor puede elegir si ofrece envío gratis o no. Por encima, Mercado Libre lo exige.
A22: 3. COSTO FIJO POR UNIDAD VENDIDA — productos < umbral despachados por Mercado Envíos
B23: Desde precio ($) ≥ | C23: Costo fijo ($)
B24: 0 | C24: 1100
B25: 15000.01 | C25: 2250
B26: 25000.01 | C26: 2700
A27: Tramos: hasta $15.000 → $1.100 · $15.000–$25.000 → $2.250 · $25.000–$33.000 → $2.700 (valores orientativos, 2do semestre 2025 / 2026). IMPORTANTE: este cargo lo pagás por cada unidad vendida despachada por Mercado Envíos (Full, correo, colecta, puntos de despacho) AUNQUE el envío lo pague el comprador. No aplica a retiro en persona. Desde el 12/03/2026 también depende del peso y las dimensiones — confirmá el valor exacto en tu panel de vendedor (Mercado Envíos > Costos).
A29: 4. COSTO DE ENVÍO POR PESO — Full o productos desde el umbral (envío gratis obligatorio)
B30: Desde peso (kg) ≥ | C30: Costo de envío ($)
B31: 0 | C31: 2500
B32: 1.01 | C32: 4500
B33: 5.01 | C33: 7500
B34: 10.01 | C34: 11000
B35: 20.01 | C35: 15500
A36: Mercado Libre NO publica esta tabla de forma oficial (depende de peso real vs. volumétrico, distancia y transportista). Son valores estimados de mercado — ajustalos con lo que veas reflejado en tus liquidaciones/facturación real de Mercado Envíos.
A38: 5. DESCUENTO EN ENVÍO POR USAR FULL (según reputación)
B39: Reputación | C39: Descuento sobre costo de envío
B40: MercadoLíder / Reputación verde | C40: 0.5
B41: Reputación amarilla / Sin reputación | C41: 0.4
B42: Reputación roja / Otras | C42: 0
A43: Bonificación de Mercado Libre para vendedores que despachan con Mercado Envíos Full, según su nivel de reputación.
A45: 6. CARGO POR CUOTAS SIN INTERÉS OFRECIDAS
B46: Cuotas ofrecidas | C46: Cargo (% sobre precio)
...

Sheet Calculadora
A1: CALCULADORA DE COSTOS, MARGEN Y RENTABILIDAD — MERCADO LIBRE ARGENTINA
A2: Completá una fila por publicación/venta. Cubre las 4 combinaciones: Full con envío gratis, Mercado Envíos sin Full con envío gratis, envío a cargo del comprador (sin envío gratis), precio por debajo y por encima de los $33.000 (umbral de envío gratis obligatorio). Los valores de tarifas se editan en la hoja "Parámetros".
A3: Filas 6-9 (fondo naranja) = 4 ejemplos resueltos, no las borres. Filas 10 en adelante = tus productos. Azul = dato que completás vos · Negro = fórmula, no tocar · Verde/rojo en Margen y Rentabilidad = referencia visual. La Ganancia usa la "Condición fiscal" de Parámetros: si sos Responsable Inscripto, el IVA de las comisiones ML se suma de vuelta (es crédito fiscal recuperable, no costo real).
A5: SKU / Producto | B5: Categoría | C5: Tipo publicación | D5: Precio de venta ($) | E5: Costo del producto ($) | F5: Otros costos directos ($) | G5: Peso (kg) | H5: Modalidad de envío | I5: ¿Envío gratis? | J5: Reputación (si es Full) | K5: Cuotas sin interés | L5: % Comisión | M5: Comisión ($) | N5: Costo fijo / envío ($) | O5: Cargo cuotas ($) | P5: Subtotal costos ML (sin IVA) | Q5: IVA s/ costos ML | R5: Almacenamiento Full ($) | S5: Total costos ML ($) | T5: Percepción IIBB (informativo) | U5: Ingreso neto recibido ($) | V5: Ganancia ($) | W5: Margen s/ precio (%) | X5: Rentabilidad s/ costo (%)
A6: EJEMPLO 1 — Zapatillas urbanas (Full, envío gratis, ≥ $33.000) | B6: Ropa y Calzado | C6: Clásica | D6: 45000 | E6: 22000 | F6: 500 | G6: 1.2 | H6: Full | I6: Sí | J6: MercadoLíder / Reputación verde | K6: 0 | L6: =IF($B6="","",IFERROR(IF($C6="Premium",INDEX(ComisionPremium,MATCH($B6,CatList,0)),INDEX(ComisionClasica,MATCH($B6,CatList,0))),0)) -> 0.135 | M6: =IF($B6="","",$D6*$L6) -> 6075 | N6: =IF($B6="","",IFERROR(IF(AND($D6<UmbralEnvioGratis,$H6<>"Retiro en punto/sucursal (sin envío)"),INDEX(CostoFijoTramo,MATCH($D6,TramoPrecioDesde,1)),0)+IF($I6="Sí",INDEX(CostoEnvioPeso,MATCH($G6,TramoPesoDesde,1))*IF($H6="Full",1-INDEX(DescuentoFull,MATCH($J6,ReputacionList,0)),1),0),0)) -> 2250 | O6: =IF($B6="","",IFERROR($D6*INDEX(CargoCuotas,MATCH($K6,CuotasList,0)),0)) -> 0 | P6: =IF($B6="","",M6+N6+O6) -> 8325 | Q6: =IF($B6="","",P6*IVAParam) -> 1748.25 | R6: =IF($B6="","",IF($H6="Full",AlmacenFull,0)) -> 300 | S6: =IF($B6="","",P6+Q6+R6) -> 10373.25 | T6: =IF($B6="","",$D6*IIBBParam) -> 1575 | U6: =IF($B6="","",$D6-$S6) -> 34626.75 | V6: =IF($B6="","",$U6-$E6-$F6+IF(CondicionFiscal="Responsable Inscripto",$Q6,0)) -> 12126.75 | W6: =IF($B6="","",IF($D6=0,0,$V6/$D6)) -> 0.26948333 | X6: =IF($B6="","",IF(($E6+$F6)=0,0,$V6/($E6+$F6))) -> 0.53896667
A7: EJEMPLO 2 — Auricular Bluetooth (Full, envío gratis, < $33.000) | B7: Electrónica, Audio y Video | C7: Clásica | D7: 18000 | E7: 9000 | F7: 300 | G7: 0.3 | H7: Full | I7: Sí | J7: Reputación amarilla / Sin reputación | K7: 3 | L7: =IF($B7="","",IFERROR(IF($C7="Premium",INDEX(ComisionPremium,MATCH($B7,CatList,0)),INDEX(ComisionClasica,MATCH($B7,CatList,0))),0)) -> 0.15 | M7: =IF($B7="","",$D7*$L7) -> 2700 | N7: =IF($B7="","",IFERROR(IF(AND($D7<UmbralEnvioGratis,$H7<>"Retiro en punto/sucursal (sin envío)"),INDEX(CostoFijoTramo,MATCH($D7,TramoPrecioDesde,1)),0)+IF($I7="Sí",INDEX(CostoEnvioPeso,MATCH($G7,TramoPesoDesde,1))*IF($H7="Full",1-INDEX(DescuentoFull,MATCH($J7,ReputacionList,0)),1),0),0)) -> 3750 | O7: =IF($B7="","",IFERROR($D7*INDEX(CargoCuotas,MATCH($K7,CuotasList,0)),0)) -> 1035 | P7: =IF($B7="","",M7+N7+O7) -> 7485 | Q7: =IF($B7="","",P7*IVAParam) -> 1571.85 | R7: =IF($B7="","",IF($H7="Full",AlmacenFull,0)) -> 300 | S7: =IF($B7="","",P7+Q7+R7) -> 9356.85 | T7: =IF($B7="","",$D7*IIBBParam) -> 630 | U7: =IF($B7="","",$D7-$S7) -> 8643.15 | V7: =IF($B7="","",$U7-$E7-$F7+IF(CondicionFiscal="Responsable Inscripto",$Q7,0)) -> -656.85 | W7: =IF($B7="","",IF($D7=0,0,$V7/$D7)) -> -0.036491667 | X7: =IF($B7="","",IF(($E7+$F7)=0,0,$V7/($E7+$F7))) -> -0.070629032
A8: EJEMPLO 3 — Repuesto para auto (sin Full, con envío gratis, < $33.000) | B8: Accesorios para Vehículos | C8: Clásica | D8: 12000 | E8: 6000 | F8: 200 | G8: 0.8 | H8: Mercado Envíos (sin Full) | I8: Sí | K8: 0 | L8: =IF($B8="","",IFERROR(IF($C8="Premium",INDEX(ComisionPremium,MATCH($B8,CatList,0)),INDEX(ComisionClasica,MATCH($B8,CatList,0))),0)) -> 0.13 | M8: =IF($B8="","",$D8*$L8) -> 1560 | N8: =IF($B8="","",IFERROR(IF(AND($D8<UmbralEnvioGratis,$H8<>"Retiro en punto/sucursal (sin envío)"),INDEX(CostoFijoTramo,MATCH($D8,TramoPrecioDesde,1)),0)+IF($I8="Sí",INDEX(CostoEnvioPeso,MATCH($G8,TramoPesoDesde,1))*IF($H8="Full",1-INDEX(DescuentoFull,MATCH($J8,ReputacionList,0)),1),0),0)) -> 3600 | O8: =IF($B8="","",IFERROR($D8*INDEX(CargoCuotas,MATCH($K8,CuotasList,0)),0)) -> 0 | P8: =IF($B8="","",M8+N8+O8) -> 5160 | Q8: =IF($B8="","",P8*IVAParam) -> 1083.6 | R8: =IF($B8="","",IF($H8="Full",AlmacenFull,0)) -> 0 | S8: =IF($B8="","",P8+Q8+R8) -> 6243.6 | T8: =IF($B8="","",$D8*IIBBParam) -> 420 | U8: =IF($B8="","",$D8-$S8) -> 5756.4 | V8: =IF($B8="","",$U8-$E8-$F8+IF(CondicionFiscal="Responsable Inscripto",$Q8,0)) -> -443.6 | W8: =IF($B8="","",IF($D8=0,0,$V8/$D8)) -> -0.036966667 | X8: =IF($B8="","",IF(($E8+$F8)=0,0,$V8/($E8+$F8))) -> -0.071548387
A9: EJEMPLO 4 — Producto económico (retiro en persona, sin Mercado Envíos, < $33.000) | B9: Hogar, Muebles y Jardín | C9: Clásica | D9: 8000 | E9: 4000 | F9: 100 | G9: 0.5 | H9: Retiro en punto/sucursal (sin envío) | I9: No | K9: 0 | L9: =IF($B9="","",IFERROR(IF($C9="Premium",INDEX(ComisionPremium,MATCH($B9,CatList,0)),INDEX(ComisionClasica,MATCH($B9,CatList,0))),0)) -> 0.135 | M9: =IF($B9="","",$D9*$L9) -> 1080 | N9: =IF($B9="","",IFERROR(IF(AND($D9<UmbralEnvioGratis,$H9<>"Retiro en punto/sucursal (sin envío)"),INDEX(CostoFijoTramo,MATCH($D9,TramoPrecioDesde,1)),0)+IF($I9="Sí",INDEX(CostoEnvioPeso,MATCH($G9,TramoPesoDesde,1))*IF($H9="Full",1-INDEX(DescuentoFull,MATCH($J9,ReputacionList,0)),1),0),0)) -> 0 | O9: =IF($B9="","",IFERROR($D9*INDEX(CargoCuotas,MATCH($K9,CuotasList,0)),0)) -> 0 | P9: =IF($B9="","",M9+N9+O9) -> 1080 | Q9: =IF($B9="","",P9*IVAParam) -> 226.8 | R9: =IF($B9="","",IF($H9="Full",AlmacenFull,0)) -> 0 | S9: =IF($B9="","",P9+Q9+R9) -> 1306.8 | T9: =IF($B9="","",$D9*IIBBParam) -> 280 | U9: =IF($B9="","",$D9-$S9) -> 6693.2 | V9: =IF($B9="","",$U9-$E9-$F9+IF(CondicionFiscal="Responsable Inscripto",$Q9,0)) -> 2593.2 | W9: =IF($B9="","",IF($D9=0,0,$V9/$D9)) -> 0.32415 | X9: =IF($B9="","",IF(($E9+$F9)=0,0,$V9/($E9+$F9))) -> 0.6324878
L10: =IF($B10="","",IFERROR(IF($C10="Premium",INDEX(ComisionPremium,MATCH($B10,CatList,0)),INDEX(ComisionClasica,MATCH($B10,CatList,0))),0)) | M10: =IF($B10="","",$D10*$L10) | N10: =IF($B10="","",IFERROR(IF(AND($D10<UmbralEnvioGratis,$H10<>"Retiro en punto/sucursal (sin envío)"),INDEX(CostoFijoTramo,MATCH($D10,TramoPrecioDesde,1)),0)+IF($I10="Sí",INDEX(CostoEnvioPeso,MATCH($G10,TramoPesoDesde,1))*IF($H10="Full",1-INDEX(DescuentoFull,MATCH($J10,ReputacionList,0)),1),0),0)) | O10: =IF($B10="","",IFERROR($D10*INDEX(CargoCuotas,MATCH($K10,CuotasList,0)),0)) | P10: =IF($B10="","",M10+N10+O10) | Q10: =IF($B10="","",P10*IVAParam) | R10: =IF($B10="","",IF($H10="Full",AlmacenFull,0)) | S10: =IF($B10="","",P10+Q10+R10) | T10: =IF($B10="","",$D10*IIBBParam) | U10: =IF($B10="","",$D10-$S10) | V10: =IF($B10="","",$U10-$E10-$F10+IF(CondicionFiscal="Responsable Inscripto",$Q10,0)) | W10: =IF($B10="","",IF($D10=0,0,$V10/$D10)) | X10: =IF($B10="","",IF(($E10+$F10)=0,0,$V10/($E10+$F10)))
L11: =IF($B11="","",IFERROR(IF($C11="Premium",INDEX(ComisionPremium,MATCH($B11,CatList,0)),INDEX(ComisionClasica,MATCH($B11,CatList,0))),0)) | M11: =IF($B11="","",$D11*$L11) | N11: =IF($B11="","",IFERROR(IF(AND($D11<UmbralEnvioGratis,$H11<>"Retiro en punto/sucursal (sin envío)"),INDEX(CostoFijoTramo,MATCH($D11,TramoPrecioDesde,1)),0)+IF($I11="Sí",INDEX(CostoEnvioPeso,MATCH($G11,TramoPesoDesde,1))*IF($H11="Full",1-INDEX(DescuentoFull,MATCH($J11,ReputacionList,0)),1),0),0)) | O11: =IF($B11="","",IFERROR($D11*INDEX(CargoCuotas,MATCH($K11,CuotasList,0)),0)) | P11: =IF($B11="","",M11+N11+O11) | Q11: =IF($B11="","",P11*IVAParam) | R11: =IF($B11="","",IF($H11="Full",AlmacenFull,0)) | S11: =IF($B11="","",P11+Q11+R11) | T11: =IF($B11="","",$D11*IIBBParam) | U11: =IF($B11="","",$D11-$S11) | V11: =IF($B11="","",$U11-$E11-$F11+IF(CondicionFiscal="Responsable Inscripto",$Q11,0)) | W11: =IF($B11="","",IF($D11=0,0,$V11/$D11)) | X11: =IF($B11="","",IF(($E11+$F11)=0,0,$V11/($E11+$F11)))
L12: =IF($B12="","",IFERROR(IF($C12="Premium",INDEX(ComisionPremium,MATCH($B12,CatList,0)),INDEX(ComisionClasica,MATCH($B12,CatList,0))),0)) | M12: =IF($B12="","",$D12*$L12) | N12: =IF($B12="","",IFERROR(IF(AND($D12<UmbralEnvioGratis,$H12<>"Retiro en punto/sucursal (sin envío)"),INDEX(CostoFijoTramo,MATCH($D12,TramoPrecioDesde,1)),0)+IF($I12="Sí",INDEX(CostoEnvioPeso,MATCH($G12,TramoPesoDesde,1))*IF($H12="Full",1-INDEX(DescuentoFull,MATCH($J12,ReputacionList,0)),1),0),0)) | O12: =IF($B12="","",IFERROR($D12*INDEX(CargoCuotas,MATCH($K12,CuotasList,0)),0)) | P12: =IF($B12="","",M12+N12+O12) | Q12: =IF($B12="","",P12*IVAParam) | R12: =IF($B12="","",IF($H12="Full",AlmacenFull,0)) | S12: =IF($B12="","",P12+Q12+R12) | T12: =IF($B12="","",$D12*IIBBParam) | U12: =IF($B12="","",$D12-$S12) | V12: =IF($B12="","",$U12-$E12-$F12+IF(CondicionFiscal="Responsable Inscripto",$Q12,0)) | W12: =IF($B12="","",IF($D12=0,0,$V12/$D12)) | X12: =IF($B12="","",IF(($E12+$F12)=0,0,$V12/($E12+$F12)))
L13: =IF($B13="","",IFERROR(IF($C13="Premium",INDEX(ComisionPremium,MATCH($B13,CatList,0)),INDEX(ComisionClasica,MATCH($B13,CatList,0))),0)) | M13: =IF($B13="","",$D13*$L13) | N13: =IF($B13="","",IFERROR(IF(AND($D13<UmbralEnvioGratis,$H13<>"Retiro en punto/sucursal (sin envío)"),INDEX(CostoFijoTramo,MATCH($D13,TramoPrecioDesde,1)),0)+IF($I13="Sí",INDEX(CostoEnvioPeso,MATCH($G13,TramoPesoDesde,1))*IF($H13="Full",1-INDEX(DescuentoFull,MATCH($J13,ReputacionList,0)),1),0),0)) | O13: =IF($B13="","",IFERROR($D13*INDEX(CargoCuotas,MATCH($K13,CuotasList,0)),0)) | P13: =IF($B13="","",M13+N13+O13) | Q13: =IF($B13="","",P13*IVAParam) | R13: =IF($B13="","",IF($H13="Full",AlmacenFull,0)) | S13: =IF($B13="","",P13+Q13+R13) | T13: =IF($B13="","",$D13*IIBBParam) | U13: =IF($B13="","",$D13-$S13) | V13: =IF($B13="","",$U13-$E13-$F13+IF(CondicionFiscal="Responsable Inscripto",$Q13,0)) | W13: =IF($B13="","",IF($D13=0,0,$V13/$D13)) | X13: =IF($B13="","",IF(($E13+$F13)=0,0,$V13/($E13+$F13)))
L14: =IF($B14="","",IFERROR(IF($C14="Premium",INDEX(ComisionPremium,MATCH($B14,CatList,0)),INDEX(ComisionClasica,MATCH($B14,CatList,0))),0)) | M14: =IF($B14="","",$D14*$L14) | N14: =IF($B14="","",IFERROR(IF(AND($D14<UmbralEnvioGratis,$H14<>"Retiro en punto/sucursal (sin envío)"),INDEX(CostoFijoTramo,MATCH($D14,TramoPrecioDesde,1)),0)+IF($I14="Sí",INDEX(CostoEnvioPeso,MATCH($G14,TramoPesoDesde,1))*IF($H14="Full",1-INDEX(DescuentoFull,MATCH($J14,ReputacionList,0)),1),0),0)) | O14: =IF($B14="","",IFERROR($D14*INDEX(CargoCuotas,MATCH($K14,CuotasList,0)),0)) | P14: =IF($B14="","",M14+N14+O14) | Q14: =IF($B14="","",P14*IVAParam) | R14: =IF($B14="","",IF($H14="Full",AlmacenFull,0)) | S14: =IF($B14="","",P14+Q14+R14) | T14: =IF($B14="","",$D14*IIBBParam) | U14: =IF($B14="","",$D14-$S14) | V14: =IF($B14="","",$U14-$E14-$F14+IF(CondicionFiscal="Responsable Inscripto",$Q14,0)) | W14: =IF($B14="","",IF($D14=0,0,$V14/$D14)) | X14: =IF($B14="","",IF(($E14+$F14)=0,0,$V14/($E14+$F14)))
L15: =IF($B15="","",IFERROR(IF($C15="Premium",INDEX(ComisionPremium,MATCH($B15,CatList,0)),INDEX(ComisionClasica,MATCH($B15,CatList,0))),0)) | M15: =IF($B15="","",$D15*$L15) | N15: =IF($B15="","",IFERROR(IF(AND($D15<UmbralEnvioGratis,$H15<>"Retiro en punto/sucursal (sin envío)"),INDEX(CostoFijoTramo,MATCH($D15,TramoPrecioDesde,1)),0)+IF($I15="Sí",INDEX(CostoEnvioPeso,MATCH($G15,TramoPesoDesde,1))*IF($H15="Full",1-INDEX(DescuentoFull,MATCH($J15,ReputacionList,0)),1),0),0)) | O15: =IF($B15="","",IFERROR($D15*INDEX(CargoCuotas,MATCH($K15,CuotasList,0)),0)) | P15: =IF($B15="","",M15+N15+O15) | Q15: =IF($B15="","",P15*IVAParam) | R15: =IF($B15="","",IF($H15="Full",AlmacenFull,0)) | S15: =IF($B15="","",P15+Q15+R15) | T15: =IF($B15="","",$D15*IIBBParam) | U15: =IF($B15="","",$D15-$S15) | V15: =IF($B15="","",$U15-$E15-$F15+IF(CondicionFiscal="Responsable Inscripto",$Q15,0)) | W15: =IF($B15="","",IF($D15=0,0,$V15/$D15)) | X15: =IF($B15="","",IF(($E15+$F15)=0,0,$V15/($E15+$F15)))
L16: =IF($B16="","",IFERROR(IF($C16="Premium",INDEX(ComisionPremium,MATCH($B16,CatList,0)),INDEX(ComisionClasica,MATCH($B16,CatList,0))),0)) | M16: =IF($B16="","",$D16*$L16) | N16: =IF($B16="","",IFERROR(IF(AND($D16<UmbralEnvioGratis,$H16<>"Retiro en punto/sucursal (sin envío)"),INDEX(CostoFijoTramo,MATCH($D16,TramoPrecioDesde,1)),0)+IF($I16="Sí",INDEX(CostoEnvioPeso,MATCH($G16,TramoPesoDesde,1))*IF($H16="Full",1-INDEX(DescuentoFull,MATCH($J16,ReputacionList,0)),1),0),0)) | O16: =IF($B16="","",IFERROR($D16*INDEX(CargoCuotas,MATCH($K16,CuotasList,0)),0)) | P16: =IF($B16="","",M16+N16+O16) | Q16: =IF($B16="","",P16*IVAParam) | R16: =IF($B16="","",IF($H16="Full",AlmacenFull,0)) | S16: =IF($B16="","",P16+Q16+R16) | T16: =IF($B16="","",$D16*IIBBParam) | U16: =IF($B16="","",$D16-$S16) | V16: =IF($B16="","",$U16-$E16-$F16+IF(CondicionFiscal="Responsable Inscripto",$Q16,0)) | W16: =IF($B16="","",IF($D16=0,0,$V16/$D16)) | X16: =IF($B16="","",IF(($E16+$F16)=0,0,$V16/($E16+$F16)))
L17: =IF($B17="","",IFERROR(IF($C17="Premium",INDEX(ComisionPremium,MATCH($B17,CatList,0)),INDEX(ComisionClasica,MATCH($B17,CatList,0))),0)) | M17: =IF($B17="","",$D17*$L17) | N17: =IF($B17="","",IFERROR(IF(AND($D17<UmbralEnvioGratis,$H17<>"Retiro en punto/sucursal (sin envío)"),INDEX(CostoFijoTramo,MATCH($D17,TramoPrecioDesde,1)),0)+IF($I17="Sí",INDEX(CostoEnvioPeso,MATCH($G17,TramoPesoDesde,1))*IF($H17="Full",1-INDEX(DescuentoFull,MATCH($J17,ReputacionList,0)),1),0),0)) | O17: =IF($B17="","",IFERROR($D17*INDEX(CargoCuotas,MATCH($K17,CuotasList,0)),0)) | P17: =IF($B17="","",M17+N17+O17) | Q17: =IF($B17="","",P17*IVAParam) | R17: =IF($B17="","",IF($H17="Full",AlmacenFull,0)) | S17: =IF($B17="","",P17+Q17+R17) | T17: =IF($B17="","",$D17*IIBBParam) | U17: =IF($B17="","",$D17-$S17) | V17: =IF($B17="","",$U17-$E17-$F17+IF(CondicionFiscal="Responsable Inscripto",$Q17,0)) | W17: =IF($B17="","",IF($D17=0,0,$V17/$D17)) | X17: =IF($B17="","",IF(($E17+$F17)=0,0,$V17/($E17+$F17)))
L18: =IF($B18="","",IFERROR(IF($C18="Premium",INDEX(ComisionPremium,MATCH($B18,CatList,0)),INDEX(ComisionClasica,MATCH($B18,CatList,0))),0)) | M18: =IF($B18="","",$D18*$L18) | N18: =IF($B18="","",IFERROR(IF(AND($D18<UmbralEnvioGratis,$H18<>"Retiro en punto/sucursal (sin envío)"),INDEX(CostoFijoTramo,MATCH($D18,TramoPrecioDesde,1)),0)+IF($I18="Sí",INDEX(CostoEnvioPeso,MATCH($G18,TramoPesoDesde,1))*IF($H18="Full",1-INDEX(DescuentoFull,MATCH($J18,ReputacionList,0)),1),0),0)) | O18: =IF($B18="","",IFERROR($D18*INDEX(CargoCuotas,MATCH($K18,CuotasList,0)),0)) | P18: =IF($B18="","",M18+N18+O18) | Q18: =IF($B18="","",P18*IVAParam) | R18: =IF($B18="","",IF($H18="Full",AlmacenFull,0)) | S18: =IF($B18="","",P18+Q18+R18) | T18: =IF($B18="","",$D18*IIBBParam) | U18: =IF($B18="","",$D18-$S18) | V18: =IF($B18="","",$U18-$E18-$F18+IF(CondicionFiscal="Responsable Inscripto",$Q18,0)) | W18: =IF($B18="","",IF($D18=0,0,$V18/$D18)) | X18: =IF($B18="","",IF(($E18+$F18)=0,0,$V18/($E18+$F18)))
L19: =IF($B19="","",IFERROR(IF($C19="Premium",INDEX(ComisionPremium,MATCH($B19,CatList,0)),INDEX(ComisionClasica,MATCH($B19,CatList,0))),0)) | M19: =IF($B19="","",$D19*$L19) | N19: =IF($B19="","",IFERROR(IF(AND($D19<UmbralEnvioGratis,$H19<>"Retiro en punto/sucursal (sin envío)"),INDEX(CostoFijoTramo,MATCH($D19,TramoPrecioDesde,1)),0)+IF($I19="Sí",INDEX(CostoEnvioPeso,MATCH($G19,TramoPesoDesde,1))*IF($H19="Full",1-INDEX(DescuentoFull,MATCH($J19,ReputacionList,0)),1),0),0)) | O19: =IF($B19="","",IFERROR($D19*INDEX(CargoCuotas,MATCH($K19,CuotasList,0)),0)) | P19: =IF($B19="","",M19+N19+O19) | Q19: =IF($B19="","",P19*IVAParam) | R19: =IF($B19="","",IF($H19="Full",AlmacenFull,0)) | S19: =IF($B19="","",P19+Q19+R19) | T19: =IF($B19="","",$D19*IIBBParam) | U19: =IF($B19="","",$D19-$S19) | V19: =IF($B19="","",$U19-$E19-$F19+IF(CondicionFiscal="Responsable Inscripto",$Q19,0)) | W19: =IF($B19="","",IF($D19=0,0,$V19/$D19)) | X19: =IF($B19="","",IF(($E19+$F19)=0,0,$V19/($E19+$F19)))
L20: =IF($B20="","",IFERROR(IF($C20="Premium",INDEX(ComisionPremium,MATCH($B20,CatList,0)),INDEX(ComisionClasica,MATCH($B20,CatList,0))),0)) | M20: =IF($B20="","",$D20*$L20) | N20: =IF($B20="","",IFERROR(IF(AND($D20<UmbralEnvioGratis,$H20<>"Retiro en punto/sucursal (sin envío)"),INDEX(CostoFijoTramo,MATCH($D20,TramoPrecioDesde,1)),0)+IF($I20="Sí",INDEX(CostoEnvioPeso,MATCH($G20,TramoPesoDesde,1))*IF($H20="Full",1-INDEX(DescuentoFull,MATCH($J20,ReputacionList,0)),1),0),0)) | O20: =IF($B20="","",IFERROR($D20*INDEX(CargoCuotas,MATCH($K20,CuotasList,0)),0)) | P20: =IF($B20="","",M20+N20+O20) | Q20: =IF($B20="","",P20*IVAParam) | R20: =IF($B20="","",IF($H20="Full",AlmacenFull,0)) | S20: =IF($B20="","",P20+Q20+R20) | T20: =IF($B20="","",$D20*IIBBParam) | U20: =IF($B20="","",$D20-$S20) | V20: =IF($B20="","",$U20-$E20-$F20+IF(CondicionFiscal="Responsable Inscripto",$Q20,0)) | W20: =IF($B20="","",IF($D20=0,0,$V20/$D20)) | X20: =IF($B20="","",IF(($E20+$F20)=0,0,$V20/($E20+$F20)))
L21: =IF($B21="","",IFERROR(IF($C21="Premium",INDEX(ComisionPremium,MATCH($B21,CatList,0)),INDEX(ComisionClasica,MATCH($B21,CatList,0))),0)) | M21: =IF($B21="","",$D21*$L21) | N21: =IF($B21="","",IFERROR(IF(AND($D21<UmbralEnvioGratis,$H21<>"Retiro en punto/sucursal (sin envío)"),INDEX(CostoFijoTramo,MATCH($D21,TramoPrecioDesde,1)),0)+IF($I21="Sí",INDEX(CostoEnvioPeso,MATCH($G21,TramoPesoDesde,1))*IF($H21="Full",1-INDEX(DescuentoFull,MATCH($J21,ReputacionList,0)),1),0),0)) | O21: =IF($B21="","",IFERROR($D21*INDEX(CargoCuotas,MATCH($K21,CuotasList,0)),0)) | P21: =IF($B21="","",M21+N21+O21) | Q21: =IF($B21="","",P21*IVAParam) | R21: =IF($B21="","",IF($H21="Full",AlmacenFull,0)) | S21: =IF($B21="","",P21+Q21+R21) | T21: =IF($B21="","",$D21*IIBBParam) | U21: =IF($B21="","",$D21-$S21) | V21: =IF($B21="","",$U21-$E21-$F21+IF(CondicionFiscal="Responsable Inscripto",$Q21,0)) | W21: =IF($B21="","",IF($D21=0,0,$V21/$D21)) | X21: =IF($B21="","",IF(($E21+$F21)=0,0,$V21/($E21+$F21)))
... L29: =IF($B29="","",IFERROR(IF($C29="Premium",INDEX(ComisionPremium,MATCH($B29,CatList,0)),INDEX(ComisionClasica,MATCH($B29,CatList,0))),0)) | M29: =IF($B29="","",$D29*$L29) | N29: =IF($B29="","",IFERROR(IF(AND($D29<UmbralEnvioGratis,$H29<>"Retiro en punto/sucursal (sin envío)"),INDEX(CostoFijoTramo,MATCH($D29,TramoPrecioDesde,1)),0)+IF($I29="Sí",INDEX(CostoEnvioPeso,MATCH($G29,TramoPesoDesde,1))*IF($H29="Full",1-INDEX(DescuentoFull,MATCH($J29,ReputacionList,0)),1),0),0)) | O29: =IF($B29="","",IFERROR($D29*INDEX(CargoCuotas,MATCH($K29,CuotasList,0)),0)) | P29: =IF($B29="","",M29+N29+O29) | Q29: =IF($B29="","",P29*IVAParam) | R29: =IF($B29="","",IF($H29="Full",AlmacenFull,0)) | S29: =IF($B29="","",P29+Q29+R29) | T29: =IF($B29="","",$D29*IIBBParam) | U29: =IF($B29="","",$D29-$S29) | V29: =IF($B29="","",$U29-$E29-$F29+IF(CondicionFiscal="Responsable Inscripto",$Q29,0)) | W29: =IF($B29="","",IF($D29=0,0,$V29/$D29)) | X29: =IF($B29="","",IF(($E29+$F29)=0,0,$V29/($E29+$F29)))

Sheet Resumen
A1: RESUMEN — TUS PRODUCTOS EN MERCADO LIBRE
A2: Se calcula solo con las filas de la hoja "Calculadora" que tengan categoría cargada (ejemplos + tus productos). Se actualiza solo al agregar filas.
A4: Productos cargados | D4: Precio de venta promedio | G4: Ganancia total ($)
A5: =COUNT(Calculadora!$D$6:$D$29) -> 4 | D5: =IFERROR(AVERAGE(Calculadora!$D$6:$D$29),0) -> 20750 | G5: =SUM(Calculadora!$V$6:$V$29) -> 13619.5
A7: Margen promedio (s/ precio) | D7: Rentabilidad promedio (s/ costo) | G7: Productos con rentabilidad negativa
A8: =IFERROR(AVERAGE(Calculadora!$W$6:$W$29),0) -> 0.13004375 | D8: =IFERROR(AVERAGE(Calculadora!$X$6:$X$29),0) -> 0.25731926 | G8: =COUNTIFS(Calculadora!$X$6:$X$29,"<0") -> 2
A10: PRODUCTO MÁS Y MENOS RENTABLE
A11: Más rentable | D11: Menos rentable
A12: =IFERROR(INDEX(Calculadora!$A$6:$A$29,MATCH(MAX(Calculadora!$X$6:$X$29),Calculadora!$X$6:$X$29,0)),"—") -> EJEMPLO 4 — Producto económico (retiro en persona, sin Mercado Envíos, < $33.000) | D12: =IFERROR(INDEX(Calculadora!$A$6:$A$29,MATCH(MIN(Calculadora!$X$6:$X$29),Calculadora!$X$6:$X$29,0)),"—") -> EJEMPLO 3 — Repuesto para auto (sin Full, con envío gratis, < $33.000)
A13: =IFERROR(MAX(Calculadora!$X$6:$X$29),0) -> 0.6324878 | D13: =IFERROR(MIN(Calculadora!$X$6:$X$29),0) -> -0.071548387
A15: Si hay productos empatados en rentabilidad, la fórmula muestra el primero que encuentra en la lista.

Sheet Notas y Fuentes
A1: NOTAS, SUPUESTOS Y FUENTES
A3: Cómo está armado este archivo
A4: • Hoja "Parámetros": todas las tarifas de Mercado Libre editables en un solo lugar (comisión por categoría, costo fijo por tramo de precio, costo de envío por peso, descuento Full, cargo por cuotas, IVA, IIBB, almacenamiento Full).
A5: • Hoja "Calculadora": una fila por publicación/venta. Filas 6-9 son 4 ejemplos resueltos que cubren los 4 escenarios pedidos: venta Full con envío gratis, venta sin Full con envío gratis, venta con envío a cargo del comprador, y precios por encima/por debajo de $33.000. Desde la fila 10 podés cargar tus propios productos.
A6: • Hoja "Resumen": KPIs agregados de todos los productos cargados en la Calculadora — cantidad, precio/margen/rentabilidad promedio, ganancia total, alerta de productos con rentabilidad negativa, y cuál es tu producto más y menos rentable.
A7: • Margen = Ganancia / Precio de venta. Rentabilidad = Ganancia / (Costo del producto + otros costos directos). Son dos métricas distintas a propósito: el margen te dice qué % del precio te queda, la rentabilidad te dice cuánto ganás en relación a lo que invertiste.
A9: Supuestos importantes (revisar antes de tomar decisiones de precio)
A10: 1. Los % de comisión por categoría varían según sub-categoría, provincia y tipo de publicación. Los valores de la hoja Parámetros son un promedio de mercado 2026 — Mercado Libre te muestra el % exacto cuando publicás el producto; usá ese valor real.
A11: 2. El costo fijo por unidad vendida (productos < $33.000) se paga por cada venta despachada por Mercado Envíos (Full, correo, colecta, puntos de despacho) AUNQUE el envío lo pague el comprador — solo se evita con retiro en persona. Desde el 12/03/2026 depende también del peso y las dimensiones, no solo del precio. Esta planilla simplifica usando 3 tramos de precio — ajustalos si tus productos son muy pesados/voluminosos para su rango de precio. Si además ofrecés envío gratis por debajo del umbral, el costo de envío (tramo por peso) se suma al costo fijo.
A12: 3. La tabla de costo de envío por peso (Full / precio ≥ $33.000) NO es información pública de Mercado Libre — son valores estimados de mercado. Reemplazalos por los valores reales que veas en tus liquidaciones (Mercado Envíos > Costos, o tu resumen de cuenta).
A13: 4. El costo de almacenamiento Full es un promedio mensual estimado por unidad. El costo real es diario y depende del tamaño/volumen del producto — ajustalo con tu panel de Fulfillment (vendedores.mercadolibre.com.ar).
A14: 5. La percepción de IIBB (informativo, columna T de la Calculadora) es un anticipo de impuesto, no un costo definitivo: se recupera como crédito fiscal en tu DDJJ de Ingresos Brutos. Por eso no se resta en Margen ni en Rentabilidad. Si sos Monotributista, normalmente no te retienen IIBB — en ese caso poné 0% en Parámetros!C55.
... A36: Estos son artículos de terceros (agencias/consultoras de e-commerce) y páginas de ayuda oficiales de Mercado Libre, relevados en julio de 2026. Mercado Libre actualiza tarifas con frecuencia (la última suba de comisiones fue en marzo de 2026) — antes de fijar precios, comprobá los valores vigentes en tu cuenta de vendedor.
